<?xml version="1.0" encoding="utf-8"?>
<mujoco>
    <include file="../scene/basic_scene.xml"/>
    <include file="../objects/assets/_display_dependencies.xml"/>
    <include file="../objects/assets/xyz_base_dependencies.xml"/>

    <worldbody>
        <include file="../objects/assets/xyz_base.xml"/>

        <body name="drawer0" pos="-0.4 0.85 0">
            <!-- <include file="../objects/assets/drawer.xml"/> -->
            <body childclass="drawer_base">
            <body name="drawercase_link0" pos="0 0 0.084">
                <geom name="drawercase_tmp0" material="drawer_beige" mesh="drawercase"/>
                <geom class="drawer_col" pos="-0.11 0 0" size="0.008 0.1 0.084" type="box" mass=".05"/>
                <geom class="drawer_col" pos="0.11 0 0" size="0.008 0.1 0.084" type="box" mass=".05"/>
                <geom class="drawer_col" pos="0 0.092 -0.008" size="0.102 0.008 0.076" type="box" mass=".05"/>
                <geom class="drawer_col" pos="0 -0.008 -0.07" size="0.102 0.092 0.014" type="box" mass=".05"/>
                <geom class="drawer_col" pos="0 0 0.076" size="0.102 0.1 0.008" type="box" mass=".05"/>
                <body name="drawer_link0" pos="0 -0.01 0.006">
                    <joint type="slide" range="-0.16 0" axis="0 1 0" name="drawer_goal_slidey0" pos="0 0 0" damping="2"/>
                    <geom name="drawer_tmp0" material="drawer_beige" mesh="drawer"/>
                    <geom material="drawer_white" mesh="drawerhandle" pos="0 -0.114 0" name="objGeom0"/>
                    <geom class="drawer_col" pos="0 -0.082 0.008" size="0.1 0.008 0.052" type="box" mass=".04"/>
                    <geom class="drawer_col" pos="0 0.082 0.008" size="0.1 0.008 0.052" type="box" mass=".04"/>
                    <geom class="drawer_col" pos="-0.092 0 0.008" size="0.008 0.074 0.052" type="box" mass=".04"/>
                    <geom class="drawer_col" pos="0.092 0 0.008" size="0.008 0.074 0.052" type="box" mass=".04"/>
                    <geom class="drawer_col" pos="0 0 -0.052" size="0.1 0.09 0.008" type="box" mass=".04" friction="100. 100. 100."/>
                    <geom class="drawer_col" euler="1.571 0 0" pos="-0.05 -0.12 0.0" size="0.009 0.03" type="capsule" mass=".06"/>
                    <geom class="drawer_col" euler="0 1.57 0" pos="0 -0.15 0" size="0.009 0.05" type="capsule" mass=".06"/>
                    <geom class="drawer_col" euler="1.57 0 0" pos="0.05 -0.12 0" size="0.009 0.03" type="capsule" mass=".06"/>
                </body>
            </body>
          </body>
        </body>

        <body name="drawer1" pos="-0.12 0.85 0">
          <body childclass="drawer_base">
            <body name="drawercase_link1" pos="0 0 0.084">
                <geom name="drawercase_tmp1" material="drawer_beige" mesh="drawercase"/>
                <geom class="drawer_col" pos="-0.11 0 0" size="0.008 0.1 0.084" type="box" mass=".05"/>
                <geom class="drawer_col" pos="0.11 0 0" size="0.008 0.1 0.084" type="box" mass=".05"/>
                <geom class="drawer_col" pos="0 0.092 -0.008" size="0.102 0.008 0.076" type="box" mass=".05"/>
                <geom class="drawer_col" pos="0 -0.008 -0.07" size="0.102 0.092 0.014" type="box" mass=".05"/>
                <geom class="drawer_col" pos="0 0 0.076" size="0.102 0.1 0.008" type="box" mass=".05"/>
                <body name="drawer_link1" pos="0 -0.01 0.006">
                    <joint type="slide" range="-0.16 0" axis="0 1 0" name="drawer_goal_slidey1" pos="0 0 0" damping="2"/>
                    <geom name="drawer_tmp1" material="drawer_beige" mesh="drawer"/>
                    <geom material="drawer_white" mesh="drawerhandle" pos="0 -0.114 0" name="objGeom1"/>
                    <geom class="drawer_col" pos="0 -0.082 0.008" size="0.1 0.008 0.052" type="box" mass=".04"/>
                    <geom class="drawer_col" pos="0 0.082 0.008" size="0.1 0.008 0.052" type="box" mass=".04"/>
                    <geom class="drawer_col" pos="-0.092 0 0.008" size="0.008 0.074 0.052" type="box" mass=".04"/>
                    <geom class="drawer_col" pos="0.092 0 0.008" size="0.008 0.074 0.052" type="box" mass=".04"/>
                    <geom class="drawer_col" pos="0 0 -0.052" size="0.1 0.09 0.008" type="box" mass=".04" friction="100. 100. 100."/>
                    <geom class="drawer_col" euler="1.571 0 0" pos="-0.05 -0.12 0.0" size="0.009 0.03" type="capsule" mass=".06"/>
                    <geom class="drawer_col" euler="0 1.57 0" pos="0 -0.15 0" size="0.009 0.05" type="capsule" mass=".06"/>
                    <geom class="drawer_col" euler="1.57 0 0" pos="0.05 -0.12 0" size="0.009 0.03" type="capsule" mass=".06"/>
                </body>
            </body>
          </body>
            <!-- <include file="../objects/assets/drawer.xml"/> -->
        </body>

        <body name="drawer2" pos="0.4 0.85 0">
          <!-- <include file="../objects/assets/drawer.xml"/> -->
          <body childclass="drawer_base">
            <body name="drawercase_link2" pos="0 0 0.084">
                <geom name="drawercase_tmp2" material="drawer_beige" mesh="drawercase"/>
                <geom class="drawer_col" pos="-0.11 0 0" size="0.008 0.1 0.084" type="box" mass=".05"/>
                <geom class="drawer_col" pos="0.11 0 0" size="0.008 0.1 0.084" type="box" mass=".05"/>
                <geom class="drawer_col" pos="0 0.092 -0.008" size="0.102 0.008 0.076" type="box" mass=".05"/>
                <geom class="drawer_col" pos="0 -0.008 -0.07" size="0.102 0.092 0.014" type="box" mass=".05"/>
                <geom class="drawer_col" pos="0 0 0.076" size="0.102 0.1 0.008" type="box" mass=".05"/>
                <body name="drawer_link2" pos="0 -0.01 0.006">
                    <joint type="slide" range="-0.16 0" axis="0 1 0" name="drawer_goal_slidey2" pos="0 0 0" damping="2"/>
                    <geom name="drawer_tmp2" material="drawer_beige" mesh="drawer"/>
                    <geom material="drawer_white" mesh="drawerhandle" pos="0 -0.114 0" name="objGeom2"/>
                    <geom class="drawer_col" pos="0 -0.082 0.008" size="0.1 0.008 0.052" type="box" mass=".04"/>
                    <geom class="drawer_col" pos="0 0.082 0.008" size="0.1 0.008 0.052" type="box" mass=".04"/>
                    <geom class="drawer_col" pos="-0.092 0 0.008" size="0.008 0.074 0.052" type="box" mass=".04"/>
                    <geom class="drawer_col" pos="0.092 0 0.008" size="0.008 0.074 0.052" type="box" mass=".04"/>
                    <geom class="drawer_col" pos="0 0 -0.052" size="0.1 0.09 0.008" type="box" mass=".04" friction="100. 100. 100."/>
                    <geom class="drawer_col" euler="1.571 0 0" pos="-0.05 -0.12 0.0" size="0.009 0.03" type="capsule" mass=".06"/>
                    <geom class="drawer_col" euler="0 1.57 0" pos="0 -0.15 0" size="0.009 0.05" type="capsule" mass=".06"/>
                    <geom class="drawer_col" euler="1.57 0 0" pos="0.05 -0.12 0" size="0.009 0.03" type="capsule" mass=".06"/>
                </body>
            </body>
          </body>
        </body>

        <body name="coffee_machine" pos="0.12 0.85 0">
          <include file="../objects/assets/coffeemachine.xml"/>
        </body>
        
        <body name="obj0" pos="-0.4 0.3 0.1">
          <joint name="mug_obj0" type="free"/>
          <!-- <include file="../objects/assets/mug.xml"/> -->
          <body childclass="cm_base" name="mug0">

            <geom name="mug0" mesh="mug" pos="0 0 0.034" material="cmwhite"/>
            <geom name="handle0" material="cmwhite" euler="1.571 0 0" mesh="handle" pos="0.039 0 0.047"/>
            <geom class="cm_col" pos="0 0 0.035" size="0.028 0.033" type="cylinder" mass=".1" friction="100. 0. 0."/>
            <geom class="cm_col" euler="1.57 0 0" pos="0.034 0 0.042" size="0.02 0.005" type="cylinder" mass=".01" friction="100. 0. 0."/>

            <site name="objSite0" size="0.01" rgba="0 0 0 0"/>
          </body>
        </body>

        <body name="obj1" pos="0 0.3 0.1">
          <joint name="mug_obj1" type="free"/>
          <body childclass="cm_base" name="mug1">

            <geom name="mug1" mesh="mug" pos="0 0 0.034" material="cmwhite"/>
            <geom name="handle1" material="cmwhite" euler="1.571 0 0" mesh="handle" pos="0.039 0 0.047"/>
            <geom class="cm_col" pos="0 0 0.035" size="0.028 0.033" type="cylinder" mass=".1" friction="100. 0. 0."/>
            <geom class="cm_col" euler="1.57 0 0" pos="0.034 0 0.042" size="0.02 0.005" type="cylinder" mass=".01" friction="100. 0. 0."/>

            <site name="objSite1" size="0.01" rgba="0 0 0 0"/>
          </body>
          <!-- <include file="../objects/assets/mug.xml"/> -->
        </body>

        <body name="obj2" pos="0.4 0.3 0.1">
          <joint name="mug_obj2" type="free"/>
          <!-- <include file="../objects/assets/mug.xml"/> -->
          <body childclass="cm_base" name="mug2">

            <geom name="mug2" mesh="mug" pos="0 0 0.034" material="cmwhite"/>
            <geom name="handle2" material="cmwhite" euler="1.571 0 0" mesh="handle" pos="0.039 0 0.047"/>
            <geom class="cm_col" pos="0 0 0.035" size="0.028 0.033" type="cylinder" mass=".1" friction="100. 0. 0."/>
            <geom class="cm_col" euler="1.57 0 0" pos="0.034 0 0.042" size="0.02 0.005" type="cylinder" mass=".01" friction="100. 0. 0."/>

            <site name="objSite2" size="0.01" rgba="0 0 0 0"/>
          </body>
        </body>

    </worldbody>

    <actuator>
        <position ctrllimited="true" ctrlrange="-1 1" joint="r_close" kp="400"  user="1"/>
        <position ctrllimited="true" ctrlrange="-1 1" joint="l_close" kp="400"  user="1"/>
    </actuator>
    <equality>
        <weld body1="mocap" body2="hand" solref="0.02 1"></weld>
    </equality>
</mujoco>
